Workbook

Sheet TODOS LOS ANIOS
A2: FECHA | B2: 31.12.2013 | C2: 31.12.2014 | D2: 31.12.2015 | E2: 31.12.2016 | F2: 31.12.2017 | G2: 31.12.2018 | H2: 31.12.2019 | I2: 31.12.2020 | J2: ='ESP $'!C4 -> 31.12.2021 | K2: ='ESP $'!D4 -> 31.12.2022 | L2: ='ESP $'!E4 -> 31.12.2023 | M2: ='ESP $'!F4 -> 31.12.2024
A3: VENTAS | B3: 1029960482 | C3: 1156286375 | D3: 1002161191 | E3: 1046310986 | F3: 1395120800 | G3: 1467668602 | H3: 1239945000 | I3: 476205904 | J3: ='ER $'!C7 -> 7.3284191e+08 | K3: ='ER $'!D7 -> 1.6493669e+09 | L3: ='ER $'!E7 -> 2417205313 | M3: ='ER $'!F7 -> 1674689775
A4: RESULTADO NETO | B4: 35846930 | C4: 70726469 | D4: 64697240 | E4: 77174187 | F4: 95452431 | G4: 66400410 | H4: -14612526 | I4: -72785893 | J4: ='ER $'!C20 -> 48300212 | K4: ='ER $'!D20 -> 2.1300813e+08 | L4: ='ER $'!E20 -> 303814749 | M4: ='ER $'!F20 -> 94227753

Sheet ESP $
B1: NADAL Y ZACCARO S.A
B2: ESTADO DE SITUACION FINANCIERA CONSOLIDADO AL 31.12.2024
C4: 31.12.2021 | D4: 31.12.2022 | E4: 31.12.2023 | F4: 31.12.2024
C5: $ | D5: $ | E5: $ | F5: $
B6: ACTIVO
B7: Activo corriente
B8: Caja y Bancos (Nota 1) | C8: 72432876 | D8: 24455708 | E8: 3.4742177e+08 | F8: 4.3268525e+08
B9: Cuentas por Cobrar (Nota 2) | C9: 36881976 | D9: 4.2868968e+08 | E9: 2.9942916e+08 | F9: 3.1200247e+08
B10: Otros Créditos (Nota 3) | C10: 64085900 | D10: 78337428 | E10: 1.0817161e+08 | F10: 1.179089e+08
B11: Bienes de Cambio (Nota 4) | C11: 8332470.9 | D11: 7698183.8 | E11: 5042050.1 | F11: 29288207
B12: Inversiones (Nota 5) | C12: 0 | D12: 14256233 | E12: 8710545.1 | F12: 0
B13: Total del activo corriente | C13: =SUM(C8:C12) -> 1.8173322e+08 | D13: =SUM(D8:D12) -> 5.5343724e+08 | E13: =SUM(E8:E12) -> 7.6877514e+08 | F13: =SUM(F8:F12) -> 8.9188483e+08
B15: Activo no corriente
B16: Bienes de Uso (Anexo 1) | C16: 2.0047712e+08 | D16: 2.0356318e+08 | E16: 2.326019e+08 | F16: 71165900
B17: Total del activo no corriente | C17: =SUM(C16) -> 2.0047712e+08 | D17: =SUM(D16) -> 2.0356318e+08 | E17: =SUM(E16) -> 2.326019e+08 | F17: =SUM(F16) -> 71165900
B19: Total del activo | C19: =+C17+C13 -> 3.8221035e+08 | D19: =+D17+D13 -> 7.5700041e+08 | E19: =+E17+E13 -> 1.001377e+09 | F19: =+F17+F13 -> 9.6305073e+08
B21: PASIVO
B22: Pasivo corriente
B23: Deudas Comerciales (Nota 6) | C23: 0 | D23: 0 | E23: 0 | F23: 8427833.3
B24: Deudas Financieras (Nota 7) | C24: 73742346 | D24: 1.5694424e+08 | E24: 91250550 | F24: 1.1094604e+08
B25: Deudas Sociales (Nota 8) | C25: 34592332 | D25: 29954526 | E25: 31472461 | F25: 23133830
B26: Deudas Fiscales (Nota 9) | C26: 57523876 | D26: 1.7040991e+08 | E26: 1.8728983e+08 | F26: 1.1998352e+08
B27: Otras Deudas (Nota 10) | C27: 7322027.6 | D27: 0 | E27: 0 | F27: 0
B28: Total del pasivo corriente | C28: =SUM(C23:C27) -> 1.7318058e+08 | D28: =SUM(D23:D27) -> 3.5730868e+08 | E28: =SUM(E23:E27) -> 3.1001284e+08 | F28: =SUM(F23:F27) -> 2.6249122e+08
B30: Pasivo no corriente
B31: Deudas Fiscales (Nota 8) | C31: 16312719 | D31: 6970655.1 | E31: 0 | F31: 0
B32: Total del pasivo no corriente | C32: =SUM(C31) -> 16312719 | D32: =SUM(D31) -> 6970655.1 | E32: =SUM(E31) -> 0 | F32: =SUM(F31) -> 0
B34: Total del pasivo | C34: =+C28+C32 -> 1.894933e+08 | D34: =+D28+D32 -> 3.6427933e+08 | E34: =+E28+E32 -> 3.1001284e+08 | F34: =+F28+F32 -> 2.6249122e+08
B36: PATRIMONIO NETO (según estado de cambios en el patrimonio)
B37: Según Estado Respectivo | C37: 1.9271704e+08 | D37: 3.9274354e+08 | E37: 6.9136419e+08 | F37: 7.0055951e+08
B38: TOTAL PATRIMONIO NETO | C38: =SUM(C37) -> 1.9271704e+08 | D38: =SUM(D37) -> 3.9274354e+08 | E38: =SUM(E37) -> 6.9136419e+08 | F38: =SUM(F37) -> 7.0055951e+08
B39: TOTAL PASIVO Y PATRIMONIO NETO | C39: =+C34+C38 -> 3.8221035e+08 | D39: =+D34+D38 -> 7.5702287e+08 | E39: =+E34+E38 -> 1.001377e+09 | F39: =+F34+F38 -> 9.6305073e+08
B42: Cantidad de Acciones | C42: 3000 | D42: 3000 | E42: 3000 | F42: 3000 | N42: Anio | O42: =B38 -> TOTAL PATRIMONIO NETO | P42: TOTAL PASIVO
B43: Valor Libro de la Acción | C43: =+C38/C42 -> 64239.015 | D43: =+D38/D42 -> 130914.51 | E43: =+E38/E42 -> 230454.73 | F43: =+F38/F42 -> 233519.84 | N43: =C4 -> 31.12.2021 | O43: =C38 -> 1.9271704e+08 | P43: =C34 -> 1.894933e+08
N44: =D4 -> 31.12.2022 | O44: =D38 -> 3.9274354e+08 | P44: =D34 -> 3.6427933e+08
N45: =E4 -> 31.12.2023 | O45: =E38 -> 6.9136419e+08 | P45: =E34 -> 3.1001284e+08
N46: =F4 -> 31.12.2024 | O46: =F38 -> 7.0055951e+08 | P46: =F34 -> 2.6249122e+08

Sheet ER $
B1: NADAL Y ZACCARO S.A
B2: ESTADO DE RESULTADOS INTEGRAL CONSOLIDADO AL 31.12.2024
C4: 31.12.2021 | D4: 31.12.2022 | E4: 31.12.2023 | F4: 31.12.2024
C5: $ | D5: $ | E5: $ | F5: $
B7: Ingresos por ventas y servicios | C7: 7.3284191e+08 | D7: 1.6493669e+09 | E7: 2417205313 | F7: 1674689775
B8: Costos operativos (Anexo II) | C8: -6.9086989e+08 | D8: -1.2483468e+09 | E8: -1272633202 | F8: -983362892
B9: Resultado bruto | C9: 41972021 | D9: 4.0102011e+08 | E9: =E7+E8 -> 1144572111 | F9: =+F7+F8 -> 691326883
B10: Gastos
B11: Gastos de administraición (Anexo III) | C11: -741494.48 | D11: -7219208.1 | E11: -608426 | F11: -643876
B12: Gastos de comercialización (Anexo III) | C12: -50041287 | D12: -1.3429401e+08 | E12: -188463889 | F12: -152236169
B13: Resultado operativo | C13: =C9+C11+C12 -> -8810760.7 | D13: =D9+D11+D12 -> 2.595069e+08 | E13: =E9+E11+E12 -> 955499796 | F13: =SUM(F9:F12) -> 538446838
B14: Gastos Financ. Y Otros, incluido el Recpam (Anexo III) | C14: 56777162 | D14: 38857176 | E14: -540757210 | F14: -401210536
B15: Otros Ingresos | C15: 6959634.8 | D15: 8223102.6 | E15: 44638020 | F15: 18284750
B16: Resultado antes del impuesto a las ganancias | C16: 54926036 | D16: 3.0658717e+08 | E16: =E13+E14+E15 -> 459380606 | F16: =SUM(F13:F15) -> 155521052
B17: Impuesto a las ganancias | C17: -6625824.1 | D17: -93579045 | E17: -155565855 | F17: -61293299
B18: Resultado ordinario | C18: 48300212 | D18: 2.1300813e+08 | E18: 303814749 | F18: =SUM(F16:F17) -> 94227753
B20: RESULTADO INTEGRAL DEL EJERCICIO | C20: =C18 -> 48300212 | D20: =D18 -> 2.1300813e+08 | E20: =E18 -> 303814749 | F20: =+F18 -> 94227753
B23: Resultado por accion bàsico
B24: Resultado integral del ejercicio | C24: =+C20 -> 48300212 | D24: =+D20 -> 2.1300813e+08 | E24: =+E20 -> 303814749 | F24: =+F20 -> 94227753
B25: Cantidad acciones circulacion | C25: 3000 | D25: 3000 | E25: 3000 | F25: 3000
B26: Resultado del ejercicio por accion | C26: =+C24/C25 -> 16100.071 | D26: =+D24/D25 -> 71002.71 | E26: =+E24/E25 -> 101271.58 | F26: =+F24/F25 -> 31409.251

Sheet INDICADORES
B2: NADAL Y ZACCARO S.A
B3: Indicadores Económico - Financieros
B5: Datos de Balance (al cierre de cada ejercicio) | D5: 2021 | E5: 2022 | F5: 2023 | G5: 2024
B6: Resultados
B7: Ventas | C7: $ | D7: ='ER $'!C7/1000000 -> 732.84191 | E7: ='ER $'!D7/1000000 -> 1649.3669 | F7: ='ER $'!E7/1000000 -> 2417.2053 | G7: ='ER $'!F7/1000000 -> 1674.6898
B8: Utilidad Bruta | C8: $ | D8: ='ER $'!C9/1000000 -> 41.972021 | E8: ='ER $'!D9/1000000 -> 401.02011 | F8: ='ER $'!E9/1000000 -> 1144.5721 | G8: ='ER $'!F9/1000000 -> 691.32688
B9: Depreciaciones | C9: $ | D9: =COSTOS!B11/1000000 -> 18.171378 | E9: =COSTOS!C11/1000000 -> 23.218786 | F9: =COSTOS!D11/1000000 -> 30.166319 | G9: =COSTOS!E11/1000000 -> 32.205313
B10: EBIT | C10: $ | D10: ='ER $'!C13/1000000 -> -8.8107607 | E10: ='ER $'!D13/1000000 -> 259.5069 | F10: ='ER $'!E13/1000000 -> 955.4998 | G10: ='ER $'!F13/1000000 -> 538.44684
B11: EBITDA | C11: $ | D11: =D9+D10 -> 9.3606171 | E11: =E9+E10 -> 282.72568 | F11: =F9+F10 -> 985.66611 | G11: =G9+G10 -> 570.65215
B12: Utilidad Neta | C12: $ | D12: ='ER $'!C20/1000000 -> 48.300212 | E12: ='ER $'!D20/1000000 -> 213.00813 | F12: ='ER $'!E20/1000000 -> 303.81475 | G12: ='ER $'!F20/1000000 -> 94.227753
B13: Intereses Perdidos | C13: $ | D13: =(COSTOS!B24+COSTOS!B25+COSTOS!B23+COSTOS!B26+COSTOS!B27+COSTOS!B28)/1000000 -> 18.269148 | E13: =(COSTOS!C24+COSTOS!C25+COSTOS!C23+COSTOS!C26+COSTOS!C27+COSTOS!C28)/1000000 -> 22.621229 | F13: =(COSTOS!D24+COSTOS!D25+COSTOS!D23+COSTOS!D26+COSTOS!D27+COSTOS!D28)/1000000 -> 44.704517 | G13: =(COSTOS!E24+COSTOS!E25+COSTOS!E23+COSTOS!E26+COSTOS!E27+COSTOS!E28)/1000000 -> 36.611582
B14: Dividendos | C14: $ | D14: 0 | E14: =5108753/1000000 -> 5.108753 | F14: =4768252/1000000 -> 4.768252 | G14: =15201251/1000000 -> 15.201251
B15: Situación Patrimonial | D15: 2021 | E15: 2022 | F15: 2023 | G15: 2024
B16: Activo Corriente | C16: $ | D16: ='ESP $'!C13/1000000 -> 181.73322 | E16: ='ESP $'!D13/1000000 -> 553.43724 | F16: ='ESP $'!E13/1000000 -> 768.77514 | G16: ='ESP $'!F13/1000000 -> 891.88483
B17: Activo No Corriente | C17: $ | D17: ='ESP $'!C17/1000000 -> 200.47712 | E17: ='ESP $'!D17/1000000 -> 203.56318 | F17: ='ESP $'!E17/1000000 -> 232.6019 | G17: ='ESP $'!F17/1000000 -> 71.1659
B18: Activo Total | C18: $ | D18: ='ESP $'!C19/1000000 -> 382.21035 | E18: ='ESP $'!D19/1000000 -> 757.00041 | F18: ='ESP $'!E19/1000000 -> 1001.377 | G18: ='ESP $'!F19/1000000 -> 963.05073
B19: Pasivo Corriente | C19: $ | D19: ='ESP $'!C28/1000000 -> 173.18058 | E19: ='ESP $'!D28/1000000 -> 357.30868 | F19: ='ESP $'!E28/1000000 -> 310.01284 | G19: ='ESP $'!F28/1000000 -> 262.49122
B20: Pasivo No Corriente | C20: $ | D20: ='ESP $'!C32/1000000 -> 16.312719 | E20: ='ESP $'!D32/1000000 -> 6.9706551 | F20: ='ESP $'!E32/1000000 -> 0 | G20: ='ESP $'!F32/1000000 -> 0
B21: Pasivo Total | C21: $ | D21: ='ESP $'!C34/1000000 -> 189.4933 | E21: ='ESP $'!D34/1000000 -> 364.27933 | F21: ='ESP $'!E34/1000000 -> 310.01284 | G21: ='ESP $'!F34/1000000 -> 262.49122
B22: Deuda Financiera | C22: $ | D22: ='ESP $'!C24/1000000 -> 73.742346 | E22: ='ESP $'!D24/1000000 -> 156.94424 | F22: ='ESP $'!E24/1000000 -> 91.25055 | G22: ='ESP $'!F24/1000000 -> 110.94604
B23: Patrimonio Neto | C23: $ | D23: ='ESP $'!C38/1000000 -> 192.71704 | E23: ='ESP $'!D38/1000000 -> 392.74354 | F23: ='ESP $'!E38/1000000 -> 691.36419 | G23: ='ESP $'!F38/1000000 -> 700.55951
B26: Retorno sobre la inversion | D26: 2021 | E26: 2022 | F26: 2023 | G26: 2024
B27: EBITDA / Activo Total | C27: % | D27: =+D11/D18 -> 0.024490748 | E27: =+E11/E18 -> 0.37348154 | F27: =+F11/F18 -> 0.98431068 | G27: =+G11/G18 -> 0.5925463
B28: EBIT / Activo Total | C28: % | D28: =+D10/D18 -> -0.023052125 | E28: =+E10/E18 -> 0.34280945 | F28: =+F10/F18 -> 0.95418584 | G28: =+G10/G18 -> 0.55910537
B29: Utilidad Neta / Activo Total (ROA) | C29: % | D29: =+D12/D18 -> 0.12637076 | E29: =+E12/E18 -> 0.28138443 | F29: =+F12/F18 -> 0.30339696 | G29: =+G12/G18 -> 0.097842979
B30: Utilidad Neta / Pat. Neto (ROE) | C30: % | D30: =+D12/D23 -> 0.25062761 | E30: =+E12/E23 -> 0.54235935 | F30: =+F12/F23 -> 0.43944241 | G30: =+G12/G23 -> 0.13450357
B33: Margen de Rentabilidad | D33: 2021 | E33: 2022 | F33: 2023 | G33: 2024
B34: Margen Bruto | C34: % | D34: =+D8/D7 -> 0.057272953 | E34: =+E8/E7 -> 0.24313578 | F34: =+F8/F7 -> 0.47351051 | G34: =+G8/G7 -> 0.41280892
B35: EBITDA / Ventas | C35: % | D35: =+D11/D7 -> 0.012773037 | E35: =+E11/E7 -> 0.17141466 | F35: =+F11/F7 -> 0.40777095 | G35: =+G11/G7 -> 0.34075096
B36: EBIT / Ventas | C36: % | D36: =+D10/D7 -> -0.01202273 | E36: =+E10/E7 -> 0.15733727 | F36: =+F10/F7 -> 0.39529112 | G36: =+G10/G7 -> 0.32152035
B37: Utilidad Neta / Ventas | C37: % | D37: =+D12/D7 -> 0.065908092 | E37: =+E12/E7 -> 0.12914539 | F37: =+F12/F7 -> 0.12568843 | G37: =+G12/G7 -> 0.056265796
B39: Flujo de efectivo | D39: 2021 | E39: 2022 | F39: 2023 | G39: 2024
B40: Variacion de Capex | C40: $ | E40: =('ESP $'!D16-'ESP $'!C16)/1000000 -> 3.0860529 | F40: =('ESP $'!E16-'ESP $'!D16)/1000000 -> 29.038727 | G40: =('ESP $'!F16-'ESP $'!E16)/1000000 -> -161.436
B41: Capital De Trabajo | C41: $ | D41: =('ESP $'!C9+'ESP $'!C11-'ESP $'!C23-'ESP $'!C25+'ESP $'!C10-'ESP $'!C26)/1000000 -> 17.184138 | E41: =('ESP $'!D9+'ESP $'!D11-'ESP $'!D23-'ESP $'!D25+'ESP $'!D10-'ESP $'!D26)/1000000 -> 314.36086 | F41: =('ESP $'!E9+'ESP $'!E11-'ESP $'!E23-'ESP $'!E25+'ESP $'!E10-'ESP $'!E26)/1000000 -> 193.88053 | G41: =('ESP $'!F9+'ESP $'!F11-'ESP $'!F23-'ESP $'!F25+'ESP $'!F10-'ESP $'!F26)/1000000 -> 307.6544
B42: Variacion del Capital de Trabajo | C42: $ | D42: - | E42: =E41-D41 -> 297.17672 | F42: =F41-E41 -> -120.48033 | G42: =G41-F41 -> 113.77387
B43: FCF | C43: $ | D43: - | E43: =E10*DuPont!U14+INDICADORES!E9-E42-E40 -> -96.745908 | F43: =F10*DuPont!V14+INDICADORES!F9-F42-F40 -> 753.53475 | G43: =G10*DuPont!W14+INDICADORES!G9-G42-G40 -> 406.10389
B44: ECF | C44: $ | D44: - | E44: =E10*DuPont!U14+INDICADORES!E9+INDICADORES!E22-INDICADORES!E42-E40 -> 60.198329 | F44: =F10*DuPont!V14+INDICADORES!F9+INDICADORES!F22-INDICADORES!F42-F40 -> 844.78531 | G44: =G10*DuPont!W14+INDICADORES!G9+INDICADORES!G22-INDICADORES!G42-G40 -> 517.04993
B45: CCF | C45: $ | D45: - | E45: =E10*DuPont!U14+E9+E13-E42-E40 -> -74.12468 | F45: =F10*DuPont!V14+F9+F13-F42-F40 -> 798.23927 | G45: =G10*DuPont!W14+G9+G13-G42-G40 -> 442.71548
B47: Eficiencia de Operaciones | D47: 2021 | E47: 2022 | F47: 2023 | G47: 2024
B48: Ventas / Activo total | C48: veces | D48: =+D7/D18 -> 1.9173785 | E48: =+E7/E18 -> 2.1788191 | F48: =+F7/F18 -> 2.4138813 | G48: =+G7/G18 -> 1.7389424
...

Sheet DuPont
B2: NADAL Y ZACCARO S.A | T2: Margen Operativo (EBIT / Vtas.)
B3: Identidad de Du Pont | T3: 2021 | U3: 2022 | V3: 2023 | W3: 2024
T4: =INDICADORES!D36 -> -0.01202273 | U4: =INDICADORES!E36 -> 0.15733727 | V4: =INDICADORES!F36 -> 0.39529112 | W4: =INDICADORES!G36 -> 0.32152035
B5: Contable
N7: Margen (Util. Neta / Vtas.) | T7: Carga de Intereses (EBT / EBIT)
N8: 2021 | O8: 2022 | P8: 2023 | Q8: 2024 | T8: 2021 | U8: 2022 | V8: 2023 | W8: 2024
N9: =+T4*T9*T14 -> 0.065908092 | O9: =+U4*U9*U14 -> 0.12914539 | P9: =+V4*V9*V14 -> 0.12568843 | Q9: =+W4*W9*W14 -> 0.056265796 | T9: ='ER $'!C16/'ER $'!C13 -> -6.2339721 | U9: ='ER $'!D16/'ER $'!D13 -> 1.1814221 | V9: ='ER $'!E16/'ER $'!E13 -> 0.4807752 | W9: ='ER $'!F16/'ER $'!F13 -> 0.2888327 | Y9: Afectado por RECPAM
H12: Retorno s/Activos ROA (Util. Neta / Activo) | T12: Carga Tributaria (Util. Neta / EBT)
H13: 2021 | I13: 2022 | J13: 2023 | K13: 2024 | T13: 2021 | U13: 2022 | V13: 2023 | W13: 2024
H14: =+N9*N19 -> 0.12637076 | I14: =+O9*O19 -> 0.28138443 | J14: =+P9*P19 -> 0.30339696 | K14: =+Q9*Q19 -> 0.097842979 | T14: ='ER $'!C20/'ER $'!C16 -> 0.87936825 | U14: ='ER $'!D20/'ER $'!D16 -> 0.69477182 | V14: ='ER $'!E20/'ER $'!E16 -> 0.66135737 | W14: ='ER $'!F20/'ER $'!F16 -> 0.60588423
B17: Retorno sobre Capital Propio (Util. Neta / PN) | N17: Rotacion (Vtas. / Activo)
B18: 2021 | C18: 2022 | D18: 2023 | E18: 2024 | N18: 2021 | O18: 2022 | P18: 2023 | Q18: 2024
B19: =+H14*H24 -> 0.25062761 | C19: =+I14*I24 -> 0.54235935 | D19: =+J14*J24 -> 0.43944241 | E19: =+K14*K24 -> 0.13450357 | N19: =INDICADORES!D48 -> 1.9173785 | O19: =INDICADORES!E48 -> 2.1788191 | P19: =INDICADORES!F48 -> 2.4138813 | Q19: =INDICADORES!G48 -> 1.7389424
H22: Multiplicador (Activo / PN)
H23: 2021 | I23: 2022 | J23: 2023 | K23: 2024
H24: =INDICADORES!D64 -> 1.9832721 | I24: =INDICADORES!E64 -> 1.9274675 | J24: =INDICADORES!F64 -> 1.4484074 | K24: =INDICADORES!G64 -> 1.374688

Sheet EFE
A1: ESTADO DE FLUJO DE EFECTIVO
A4: Varaciones del Efectivo
A5: DETALLE | B5: 31/12/2024 | C5: 45291 | D5: 44926 | E5: 31/12/2021
A6: Efectivo al Inicio | B6: 3.4742177e+08 | C6: 24451624 | D6: 72418820 | E6: 24743956
A7: Efectivo al cierre | B7: 4.3268525e+08 | C7: 3.4742177e+08 | D7: 24478166 | E7: 72326200
A8: Aumento Neto del Efectivo | B8: 85.263.484,60 | C8: 322.970.145,35 | D8: -47940654 | E8: 47582244
A9: Causas de la Variación del Efectivo
A11: 1. Actividades Operativas
A12: Cobranzas | B12: 1.7323603e+09 | C12: 2.47356e+09 | D12: 1.3610366e+09 | E12: 8.354417e+08
A13: Pago a Proveedores | B13: -9.8465714e+08 | C13: -1.2722052e+09 | D13: -1.1058946e+09 | E13: -5.7626377e+08
A14: Pago de Sueldos y Cargas Sociales | B14: -1.9720851e+08 | C14: -2.2837335e+08 | D14: -1.4815949e+08 | E14: -1.277151e+08
A15: Pago de Impuestos y otros gastos | B15: -1.8193387e+08 | C15: -2.4347464e+08 | D15: -65110302 | E15: -26943652
A16: Movimientos Bancarios | B16: -39889658 | C16: -54605110 | D16: -39462488 | E16: -22017776
A17: Recpam del Efectivo | B17: -2.4763406e+08 | C17: -1.8854121e+08 | D17: -28357130 | E17: -9741488.7
A18: Flujo de efvo generado por actlvld. operativas | B18: 81.037.110,96 | C18: 486.360.501,91 | D18: -25947383 | E18: 72759914
A20: 2. Actividades de Inversión
A21: Compra Venta de ME/Dif. De cambio | B21: 213.09 | C21: 1342.86 | D21: 383.8326 | E21: 190.3146
A22: Constitución/Rescate PF y FCI | B22: 7286640.2 | C22: -16129631 | D22: -20004836
A23: Compra/Venta de Bienes de Uso | B23: -15757506 | C23: 45747427 | D23: -26368944
A24: Flujo de efvo generado por actlvid. de inversión | B24: 8.470.652,70 | C24: 61.875.715,59 | D24: -46373396 | E24: 190.3146
A26: 3. Actividades de Financiación
A27: Retiros Mutuos Accionistas/Pago honorarios | B27: -25109825 | C27: -88886959 | D27: -39284572 | E27: -16863723
A28: Cobro/ Pago de Préstamos | B28: 37806851 | C28: 12627682 | D28: 63664697 | E28: -8314138
A29: Flujo de efvo generado por actlvld. de flnanc. | B29: 12.697.026,34 | C29: - 101.514.640,97 | D29: 24380124 | E29: -25177861
A30: Aumento Neto del Efectivo | B30: 85.263.484,60 | C30: 322.970.145,35 | D30: -47940654 | E30: 47582244

Sheet COSTOS
A1: RUBRO | B1: 44561 | C1: 31/12/2022 | D1: 45291 | E1: 45657 | I1: 2024 | J1: 2024 VS 2023 | K1: 2023 | L1: 2023 VS 2022 | M1: 2022 | N1: 2022 VS 2021 | O1: 2021
A2: Insumos | B2: 4.2090692e+08 | C2: 1.0284813e+09 | D2: 8.3772638e+08 | E2: 6.5488999e+08 | H2: VENTAS | I2: 1.6746898e+09 | K2: 2.4172053e+09 | M2: 1.6493669e+09 | O2: 7.3284191e+08
A3: Combustible | B3: 3921119.1 | C3: 2958945.4 | D3: 17572413 | E3: 5077835.6 | H3: COSTO OPERAT. | I3: =SUM(E2:E14) -> 1.0261012e+09 | J3: =(I3-K3)/K3 -> -0.22684469 | K3: =SUM(D2:D14) -> 1.3271605e+09 | L3: =(K3-M3)/M3 -> 0.037084322 | M3: =SUM(C2:C14) -> 1.2797035e+09 | N3: =(M3-O3)/O3 -> 1.0359705 | O3: =SUM(B2:B14) -> 6.285472e+08 | S3: 32626641
A4: Gastos Varios | B4: 19938273 | C4: 32207002 | D4: 92194753 | E4: 55428695 | H4: GASTOS COMERC. | I4: =SUM(E15) -> 643876.51 | J4: =(I4-K4)/K4 -> 0.058265709 | K4: =SUM(D15) -> 608426.13 | L4: =(K4-M4)/M4 -> -0.91562973 | M4: =SUM(C15) -> 7211380.5 | N4: =(M4-O4)/O4 -> 8.7398119 | O4: =SUM(B15) -> 740402.44 | S4: 10111624
A5: Repuestos y Reparaciones | B5: 4714505.1 | C5: 3411775.6 | D5: 1938372.8 | E5: 4838092.1 | H5: GASTOS ADMINIST. | I5: =SUM(E16:E22)+S3+S4 -> 1.5223617e+08 | J5: =(I5-K5)/K5 -> -0.19222632 | K5: =SUM(D16:D22)+S6+S7 -> 1.8846389e+08 | L5: =(K5-M5)/M5 -> 0.86216204 | M5: =SUM(C16:C22) -> 1.0120703e+08 | N5: =(M5-O5)/O5 -> 1.2957028 | O5: =SUM(B16:B22) -> 44085423
A6: Mantenimiento | B6: 795978.24 | C6: 2593082.5 | D6: 3539141 | E6: 4399508.4 | H6: GASTOS FINANC. Y OTROS | I6: =SUM(E23:E29) -> 4.0121054e+08 | J6: =(I6-K6)/K6 -> -0.25805791 | K6: =SUM(D23:D29) -> 5.4075721e+08 | L6: =(K6-M6)/M6 -> -15.015091 | M6: =SUM(C23:C29) -> -38583924 | N6: =(M6-O6)/O6 -> -0.24064401 | O6: =SUM(B23:B29) -> -50811378 | S6: 43062719
A7: Trabajos de Terceros | B7: 545886 | C7: 2969573.4 | D7: 2616194.8 | E7: 20962425 | S7: 11464542
A8: Alquileres | B8: 3909811.1 | C8: 17780527 | D8: 41428732 | E8: 30111700
A9: Sueldos y Jornales | B9: 1.0941675e+08 | C9: 1.2772254e+08 | D9: 2.1531359e+08 | E9: 1.6313321e+08
A10: Cargas Sociales | B10: 35612378 | C10: 35828706 | D10: 57322712 | E10: 50558125
A11: Amortizaciones | B11: 18171378 | C11: 23218786 | D11: 30166319 | E11: 32205313
A12: Servicio de Fletes | B12: 0 | C12: 0 | D12: 24986209 | E12: 956142.52
A13: Seguros | B13: 0 | C13: 2531289.5 | D13: 2355640.9 | E13: 3362524.4
A14: Comisiones | B14: 10614200 | C14: 0 | E14: 177605.26
A15: Gastos de Oficina | B15: 740402.44 | C15: 7211380.5 | D15: 608426.13 | E15: 643876.51
A16: Honorarios | B16: 2377879.6 | C16: 7825943.7 | D16: 5335046.6 | E16: 3834387.1
A17: Impuestos y tasas | B17: 0 | C17: 376490.03 | D17: 218686.66 | E17: 164999.51
A18: Servicios Públicos | B18: 12872322 | C18: 9931180 | D18: 7665424.6 | E18: 12873016
A19: Impuesto a los Ing. Brutos | B19: 22013062 | C19: 65904081 | D19: 96688211 | E19: 75361039
A20: Tasa Seg. E Higiene | B20: 5454659.6 | C20: 16124390 | D20: 23055537 | E20: 16392813
A21: Publicidad y Propaganda | B21: 1035788.7 | C21: 779562.43 | D21: 778419.08 | E21: 652122.66
A22: Derecho de Uso Público | B22: 331710.42 | C22: 265382.96 | D22: 195303.66 | E22: 219526.44
A23: Imp. DyC Bancarios | B23: 5882165.6 | C23: 231119.85
A24: Intereses y Gastos bancarios | B24: 5867595 | C24: 10563811 | D24: 36641869 | E24: 22976205
A25: Intereses Resarcitorios | B25: 0 | C25: 0 | D25: 1347200.6 | E25: 4948586.9
A26: Costo Vta. Bien de Uso | B26: 0 | C26: 6556482.6 | E26: 8158499.4
A27: Intereses Financieros | B27: 6519387 | C27: 5071500.4 | D27: 6713540.4 | E27: 528290.66
A28: Multas | B28: 0 | C28: 198314.59 | D28: 1907.61
A29: Recpam | B29: -69080525 | C29: -61205153 | D29: 4.9605269e+08 | E29: 3.6459895e+08
A30: TOTALES: | B30: 6.2256164e+08 | C30: 1.349538e+09 | D30: 2.0024627e+09 | E30: 1.5374535e+09

Sheet BALANCE
A1: ACTIVOS | B1: 31/12/2024 | C1: 2024 vs 2023 | D1: 31/12/2023 | E1: 2023 vs 2022 | F1: 44926 | G1: 2022 vs 2021 | H1: 44561
A2: ACTIVO CORRIENTE
A3: Caja y Bancos (Nota 1) | B3: 4.3268525e+08 | C3: =(B3-D3)/D3 -> 0.24541779 | D3: 3.4742177e+08 | E3: 1 | F3: 24455708 | G3: =(F3-H3)/H3 -> -0.66236729 | H3: 72432876
A4: Cuentas por Cobrar (Nota 2) | B4: 3.1200247e+08 | C4: =(B4-D4)/D4 -> 0.041990929 | D4: 2.9942916e+08 | E4: =(D4-F4)/F4 -> -0.30152469 | F4: 4.2868968e+08 | G4: =(F4-H4)/H4 -> 10.623284 | H4: 36881976
A5: Otros Créditos (Nota 3) | B5: 1.179089e+08 | C5: =(B5-D5)/D5 -> 0.090017072 | D5: 1.0817161e+08 | E5: =(D5-F5)/F5 -> 0.38084201 | F5: 78337428 | G5: =(F5-H5)/H5 -> 0.22238165 | H5: 64085900
A6: Bienes de Cambio (Nota 4) | B6: 29288207 | C6: =(B6-D6)/D6 -> 4.8087894 | D6: 5042050.1 | E6: =(D6-F6)/F6 -> -0.34503381 | F6: 7698183.8 | G6: =(F6-H6)/H6 -> -0.076122328 | H6: 8332470.9
A7: Inversiones (Nota 5) | C7: =(B7-D7)/D7 -> -1 | D7: 8710545.1 | E7: =(D7-F7)/F7 -> -0.38900093 | F7: 14256233 | G7: 1
A8: Total Activo Corriente | B8: 8.9188483e+08 | C8: =(B8-D8)/D8 -> 0.16013746 | D8: 7.6877514e+08 | E8: =(D8-F8)/F8 -> 0.38903545 | F8: 5.5345969e+08 | G8: =(F8-H8)/H8 -> 2.0454514 | H8: 1.8173322e+08
A9: ACTIVO NO CORRIENTE | F9: 0
A10: Bienes de Uso (Anexo 1) | B10: 71165900 | C10: =(B10-D10)/D10 -> -0.69404421 | D10: 2.326019e+08 | E10: =(D10-F10)/F10 -> 0.14265216 | F10: 2.0356318e+08 | G10: =(F10-H10)/H10 -> 0.015393542 | H10: 2.0047712e+08
A11: Total Activo no Corriente | B11: =B10 -> 71165900 | C11: =(B11-D11)/D11 -> -0.69404421 | D11: =D10 -> 2.326019e+08 | E11: =(D11-F11)/F11 -> 0.14265216 | F11: 2.0356318e+08 | G11: =(F11-H11)/H11 -> 0.015393542 | H11: 2.0047712e+08
A12: TOTAL ACTIVO | B12: 9.6305073e+08 | C12: =(B12-D12)/D12 -> -0.038273602 | D12: 1.001377e+09 | E12: =(D12-F12)/F12 -> 0.32278307 | F12: 7.5702287e+08 | G12: =(F12-H12)/H12 -> 0.98064464 | H12: 3.8221035e+08
A13: PASIVOS
A14: PASIVO CORRIENTE
A15: Deudas Comerciales (Nota 6) | B15: 8427833.3 | F15: 0
A16: Deudas Financieras (Nota 7) | B16: 1.1094604e+08 | C16: =(B16-D16)/D16 -> 0.21583966 | D16: 91250550 | E16: =(D16-F16)/F16 -> -0.4185798 | F16: 1.5694424e+08 | G16: =(F16-H16)/H16 -> 1.1282783 | H16: 73742346
A17: Deudas Sociales (Nota 8) | B17: 23133830 | C17: =(B17-D17)/D17 -> -0.2649501 | D17: 31472461 | E17: =(D17-F17)/F17 -> 0.050674654 | F17: 29954526 | G17: =(F17-H17)/H17 -> -0.13407035 | H17: 34592332
A18: Deudas Fiscales (Nota 9) | B18: 1.1998352e+08 | C18: =(B18-D18)/D18 -> -0.35936983 | D18: 1.8728983e+08 | E18: =(D18-F18)/F18 -> 0.099054812 | F18: 1.7040991e+08 | G18: =(F18-H18)/H18 -> 1.9624205 | H18: 57523876
A19: Otras Deudas (Nota 10) | F19: 0 | G19: =(F19-H19)/H19 -> -1 | H19: 7322027.6
A20: Total Pasivo Corriente | B20: 2.6249122e+08 | C20: =(B20-D20)/D20 -> -0.15328922 | D20: 3.1001284e+08 | E20: =(D20-F20)/F20 -> -0.13236687 | F20: 3.5730868e+08 | G20: =(F20-H20)/H20 -> 1.0632144 | H20: 1.7318058e+08
A21: PASIVO NO CORRIENTE
A22: Deudas Fiscales (Nota 8) | E22: =(D22-F22)/F22 -> -1 | F22: 6970655.1 | G22: =(F22-H22)/H22 -> -0.57268589 | H22: 16312719
A23: Total Pasivo No Corriente | E23: =(D23-F23)/F23 -> -1 | F23: 6970655.1 | G23: =(F23-H23)/H23 -> -0.57268589 | H23: 16312719
F24: 0
A25: TOTAL DE PASIVO | B25: 2.6249122e+08 | C25: =(B25-D25)/D25 -> -0.15328922 | D25: 3.1001284e+08 | E25: =(D25-F25)/F25 -> -0.14896943 | F25: 3.6427933e+08 | G25: =(F25-H25)/H25 -> 0.92238633 | H25: 1.894933e+08
A26: PATRIMONIO NETO
A27: Según Estado Respectivo | B27: 7.0055951e+08 | C27: =(B27-D27)/D27 -> 0.013300255 | D27: 6.9136419e+08 | E27: =(D27-F27)/F27 -> 0.76034517 | F27: 3.9274354e+08 | G27: =(F27-H27)/H27 -> 1.0379284 | H27: 1.9271704e+08
A28: TOTAL PATRIMONIO NETO | B28: 7.0055951e+08 | C28: =(B28-D28)/D28 -> 0.013300255 | D28: 6.9136419e+08 | E28: =(D28-F28)/F28 -> 0.76034517 | F28: 3.9274354e+08 | G28: =(F28-H28)/H28 -> 1.0379284 | H28: 1.9271704e+08
F29: 0
A30: TOTAL PASIVO + P.N. | B30: 9.6305073e+08 | C30: =(B30-D30)/D30 -> -0.038273602 | D30: 1.001377e+09 | E30: =(D30-F30)/F30 -> 0.32278307 | F30: 7.5702287e+08 | G30: =(F30-H30)/H30 -> 0.98064464 | H30: 3.8221035e+08

Sheet ESTADO DE RESULTADOS
A3: ESTADO DE RESULTADOS
B5: 31/12/2024 | C5: S/VENTAS | D5: 31/12/2023 | E5: S/VENTAS | F5: 2024 VS 2023 | G5: 44926 | H5: S/VENTAS | I5: 2022 VS 2023 | J5: 44561 | K5: S/VENTAS | L5: 2021 VS 2022
A6: Ingresos por ventas y servicios | B6: 1674689775 | C6: =B6/B6 -> 1 | D6: 2417205313 | E6: =D6/$D$6 -> 1 | F6: =B6/D6-1 -> -0.30717934 | G6: 1.6493669e+09 | H6: =G6/G6 -> 1 | I6: =(D6-G6)/G6 -> 0.4655352 | J6: 7.3284191e+08 | K6: =J6/J6 -> 1 | L6: =(G6-J6)/J6 -> 1.2506449
A7: Costos operativos (Anexo II) | B7: -983362892 | C7: =B7/B6 -> -0.58719108 | D7: -1272633202 | E7: =D7/$D$6 -> -0.52648949 | F7: =B7/D7-1 -> -0.22730062 | G7: -1.2483468e+09 | H7: =G7/$G$6 -> -0.75686422 | I7: =(D7-G7)/G7 -> 0.019454826 | J7: -6.9086989e+08 | K7: =J7/$J$6 -> -0.94272705 | L7: =(G7-J7)/J7 -> 0.80692029
A8: Resultado Operativo | B8: 691326882 | C8: =B8/B6 -> 0.41280892 | D8: 1144572110 | E8: =D8/$D$6 -> 0.47351051 | F8: =B8/D8-1 -> -0.39599535 | G8: 4.0102011e+08 | H8: =G8/$G$6 -> 0.24313578 | I8: =(D8-G8)/G8 -> 1.8541514 | J8: 41972021 | K8: =J8/$J$6 -> 0.057272953 | L8: =(G8-J8)/J8 -> 8.5544629
A9: Gastos de administraición (Anexo III) | B9: -643876 | C9: =B9/B6 -> -0.00038447479 | D9: -608426 | E9: =D9/$D$6 -> -0.00025170638 | F9: =B9/D9-1 -> 0.058265097 | G9: -7219208.1 | H9: =G9/$G$6 -> -0.004376957 | I9: =(D9-G9)/G9 -> -0.91572123 | J9: -741494.48 | K9: =J9/$J$6 -> -0.0010118069 | L9: =(G9-J9)/J9 -> 8.7360241
A10: Gastos de comercialización (Anexo III) | B10: -152236169 | C10: =B10/B6 -> -0.090904101 | D10: -188463889 | E10: =D10/$D$6 -> -0.077967679 | F10: =B10/D10-1 -> -0.19222632 | G10: -1.3429401e+08 | H10: =G10/$G$6 -> -0.081421548 | I10: =(D10-G10)/G10 -> 0.40336779 | J10: -50041287 | K10: =J10/$J$6 -> -0.068283877 | L10: =(G10-J10)/J10 -> 1.6836642
A11: Gastos Financ. Y Otros, incluido el Recpam (Anexo III) | B11: -401210536 | C11: =B11/B6 -> -0.23957305 | D11: -540757210 | E11: =D11/$D$6 -> -0.22371174 | F11: =B11/D11-1 -> -0.25805791 | G11: 38857176 | H11: =G11/$G$6 -> 0.023558842 | I11: =(D11-G11)/G11 -> -14.916534 | J11: 56777162 | K11: =J11/$J$6 -> 0.07747532 | L11: =(G11-J11)/J11 -> -0.31561962
A12: Otros Ingresos | B12: 18284750 | C12: =B12/B6 -> 0.010918291 | D12: 44638020 | E12: =D12/$D$6 -> 0.018466789 | F12: =B12/D12-1 -> -0.59037722 | G12: 8223102.6 | H12: =G12/$G$6 -> 0.0049856114 | I12: =(D12-G12)/G12 -> 4.4283671 | J12: 6959634.8 | K12: =J12/$J$6 -> 0.0094967751 | L12: =(G12-J12)/J12 -> 0.18154225
A13: Resultado Neto | B13: 155521050 | C13: =B13/B6 -> 0.092865588 | D13: 459380605 | E13: =D13/$D$6 -> 0.19004617 | F13: =B13/D13-1 -> -0.66145491 | G13: 3.0658717e+08 | H13: =G13/$G$6 -> 0.18588173 | I13: =(D13-G13)/G13 -> 0.49836863 | J13: 54926036 | K13: =J13/$J$6 -> 0.074949365 | L13: =(G13-J13)/J13 -> 4.5818187
A14: Impuestos a las ganancias | B14: -61293299 | C14: =B14/B6 -> -0.036599793 | D14: -155565855 | E14: =D14/$D$6 -> -0.064357733 | F14: =B14/D14-1 -> -0.60599774 | G14: -93579045 | H14: =G14/$G$6 -> -0.056736341 | I14: =(D14-G14)/G14 -> 0.66240054 | J14: -6625824.1 | K14: =J14/$J$6 -> -0.0090412734 | L14: =(G14-J14)/J14 -> 13.123382
A15: Resultado del Ejercicio | B15: 94227750 | C15: =B15/B6 -> 0.056265794 | D15: 303814749 | E15: =D15/$D$6 -> 0.12568843 | F15: =B15/D15-1 -> -0.6898513 | G15: 2.1300813e+08 | H15: =G15/$G$6 -> 0.12914539 | I15: =(D15-G15)/G15 -> 0.42630588 | J15: 48300212 | K15: =J15/$J$6 -> 0.065908092 | L15: =(G15-J15)/J15 -> 3.4100868
B20: 2024 VS 2022 | C20: 2024 VS 2021
A21: Ingresos por ventas y servicios | B21: =(B6-G6)/G6 -> 0.015353059 | C21: =(B6-J6)/J6 -> 1.2851992
A22: Costos operativos (Anexo II) | B22: =(B7-G7)/G7 -> -0.21226788 | C22: =(B7-J7)/J7 -> 0.42336915
A23: Resultado Operativo | B23: =(B8-G8)/G8 -> 0.72392071 | C23: =(B8-J8)/J8 -> 15.471136
A24: Gastos de administraición (Anexo III) | B24: =(B9-G9)/G9 -> -0.91081072 | C24: =(B9-J9)/J9 -> -0.13165099
A25: Gastos de comercialización (Anexo III) | B25: =(B10-G10)/G10 -> 0.13360357 | C25: =(B10-J10)/J10 -> 2.0422113
A26: Gastos Financ. Y Otros, incluido el Recpam (Anexo III) | B26: =(B11-G11)/G11 -> -11.325262 | C26: =(B11-J11)/J11 -> -8.066407
A27: Otros Ingresos | B27: =(B12-G12)/G12 -> 1.2235829 | C27: =(B12-J12)/J12 -> 1.6272571
A28: Resultado Neto | B28: =(B13-G13)/G13 -> -0.49273465 | C28: =(B13-J13)/J13 -> 1.8314632
A29: Impuestos a las ganancias | B29: =(B14-G14)/G14 -> -0.34501042 | C29: =(B14-J14)/J14 -> 8.250668
A30: Resultado del Ejercicio | B30: =(B15-G15)/G15 -> -0.55763308 | C30: =(B15-J15)/J15 -> 0.95087653

Sheet ratio
B3: RENTABILIDAD DEL ACTIVO | G3: EBIT | L3: SOLVENCIA | Q3: ENDEUDAMIENTO
B4: 2024 | C4: 2023 | D4: 2022 | E4: 2021 | G4: 2024 | H4: 2023 | I4: 2022 | J4: 2021 | L4: 2024 | M4: 2023 | N4: 2022 | O4: 2021 | Q4: 2024 | R4: 2023 | S4: 2022 | T4: 2021
B5: ='ESTADO DE RESULTADOS'!B13/BALANCE!B12 -> 0.16148791 | C5: ='ESTADO DE RESULTADOS'!D13/BALANCE!D12 -> 0.45874889 | D5: ='ESTADO DE RESULTADOS'!G13/BALANCE!F12 -> 0.40499064 | E5: ='ESTADO DE RESULTADOS'!J13/BALANCE!H12 -> 0.1437063 | G5: =('ESTADO DE RESULTADOS'!B8+'ESTADO DE RESULTADOS'!B9+'ESTADO DE RESULTADOS'!B10)/'ESTADO DE RESULTADOS'!B6 -> 0.32152035 | H5: =('ESTADO DE RESULTADOS'!D8+'ESTADO DE RESULTADOS'!D9+'ESTADO DE RESULTADOS'!D10)/'ESTADO DE RESULTADOS'!D6 -> 0.39529112 | I5: =('ESTADO DE RESULTADOS'!G8+'ESTADO DE RESULTADOS'!G9+'ESTADO DE RESULTADOS'!G10)/'ESTADO DE RESULTADOS'!G6 -> 0.15733727 | J5: =('ESTADO DE RESULTADOS'!J8+'ESTADO DE RESULTADOS'!J9+'ESTADO DE RESULTADOS'!J10)/'ESTADO DE RESULTADOS'!J6 -> -0.01202273 | L5: =BALANCE!B12/BALANCE!B25 -> 3.6688874 | M5: =BALANCE!D12/BALANCE!D25 -> 3.2301147 | N5: =BALANCE!F12/BALANCE!F25 -> 2.0781384 | O5: =BALANCE!H12/BALANCE!H25 -> 2.0170124 | Q5: =BALANCE!B25/BALANCE!B28 -> 0.37468796 | R5: =BALANCE!D25/BALANCE!D28 -> 0.44840743 | S5: =BALANCE!F25/BALANCE!F28 -> 0.92752469 | T5: =BALANCE!H25/BALANCE!H28 -> 0.98327214
B7: RETORNO SOBRE CAPITAL INVERTIDO | G7: RENTABILIAD DEL PATRIMONIO NETO | L7: LIQUIDEZ CORRIENTE | Q7: LIQUIDEZ ACIDA
L8: 2024 | M8: 2023 | N8: 2022 | O8: 2021 | Q8: 2024 | R8: 2023 | S8: 2022 | T8: 2021
B9: 2024 | C9: 2023 | D9: 2022 | E9: 2021 | G9: 2024 | H9: 2023 | I9: 2022 | J9: 2021 | L9: =BALANCE!B8/BALANCE!B20 -> 3.3977702 | M9: =BALANCE!D8/BALANCE!D20 -> 2.479817 | N9: =BALANCE!F8/BALANCE!F20 -> 1.548968 | O9: =BALANCE!H8/BALANCE!H20 -> 1.0493857 | Q9: =(BALANCE!B8-BALANCE!B6)/BALANCE!B20 -> 3.2861923 | R9: =(BALANCE!D8-BALANCE!D6)/BALANCE!D20 -> 2.463553 | S9: =(BALANCE!F8-BALANCE!F6)/BALANCE!F20 -> 1.5274231 | T9: =(BALANCE!H8-BALANCE!H6)/BALANCE!H20 -> 1.0012713
B10: =(('ESTADO DE RESULTADOS'!B8+'ESTADO DE RESULTADOS'!B9+'ESTADO DE RESULTADOS'!B10)*(1-0.35))/(BALANCE!B28+BALANCE!B16) -> 0.43128533 | C10: =(('ESTADO DE RESULTADOS'!D8+'ESTADO DE RESULTADOS'!D9+'ESTADO DE RESULTADOS'!D10)*(1-0.35))/(BALANCE!D28+BALANCE!D16) -> 0.79358953 | D10: =(('ESTADO DE RESULTADOS'!G8+'ESTADO DE RESULTADOS'!G9+'ESTADO DE RESULTADOS'!G10)*(1-0.35))/(BALANCE!F28+BALANCE!F16) -> 0.30686417 | E10: =(('ESTADO DE RESULTADOS'!J8+'ESTADO DE RESULTADOS'!J9+'ESTADO DE RESULTADOS'!J10)*(1-0.35))/(BALANCE!H28+BALANCE!H16) -> -0.021492935 | G10: ='ESTADO DE RESULTADOS'!B13/BALANCE!B28 -> 0.22199549 | H10: ='ESTADO DE RESULTADOS'!D13/BALANCE!D28 -> 0.6644553 | I10: ='ESTADO DE RESULTADOS'!G13/BALANCE!F28 -> 0.78062945 | J10: ='ESTADO DE RESULTADOS'!J13/BALANCE!H28 -> 0.28500871
B12: EBITDA | G12: RENTABILIDAD NETA | L12: INMOVILIZACION
B13: 2024 | C13: 2023 | D13: 2022 | E13: 2021 | G13: 2024 | H13: 2023 | I13: 2022 | J13: 2021 | L13: 2024 | M13: 2023 | N13: 2022 | O13: 2021
B14: =('ESTADO DE RESULTADOS'!B8+'ESTADO DE RESULTADOS'!B9+'ESTADO DE RESULTADOS'!B10+COSTOS!E11)/'ESTADO DE RESULTADOS'!B6 -> 0.34075096 | C14: =('ESTADO DE RESULTADOS'!D8+'ESTADO DE RESULTADOS'!D9+'ESTADO DE RESULTADOS'!D10+COSTOS!D11)/'ESTADO DE RESULTADOS'!D6 -> 0.40777095 | D14: =('ESTADO DE RESULTADOS'!G8+'ESTADO DE RESULTADOS'!G9+'ESTADO DE RESULTADOS'!G10+COSTOS!C11)/'ESTADO DE RESULTADOS'!G6 -> 0.17141466 | E14: =('ESTADO DE RESULTADOS'!J8+'ESTADO DE RESULTADOS'!J9+'ESTADO DE RESULTADOS'!J10+COSTOS!B11)/'ESTADO DE RESULTADOS'!J6 -> 0.012773037 | G14: ='ESTADO DE RESULTADOS'!C15 -> 0.056265794 | H14: ='ESTADO DE RESULTADOS'!E15 -> 0.12568843 | I14: ='ESTADO DE RESULTADOS'!H15 -> 0.12914539 | J14: ='ESTADO DE RESULTADOS'!K15 -> 0.065908092 | L14: =BALANCE!B11/BALANCE!B28 -> 0.10158437 | M14: =BALANCE!D11/BALANCE!D28 -> 0.33643904 | N14: =BALANCE!F11/BALANCE!F28 -> 0.51831069 | O14: =BALANCE!H11/BALANCE!H28 -> 1.0402667
B16: COSTO DEL FINANCIAMIENTO | G16: APALANCAMIENTO
B17: 2024 | C17: 2023 | D17: 2022 | E17: 2021 | G17: 2024 | H17: 2023 | I17: 2022 | J17: 2021
B18: =(COSTOS!E24+COSTOS!E27)/((BALANCE!B16+BALANCE!D16)/2) -> 0.23249152 | C18: =(COSTOS!D24+COSTOS!D27)/((BALANCE!D16+BALANCE!F16)/2) -> 0.34936599 | D18: =(COSTOS!C24+COSTOS!C27)/((BALANCE!F16+BALANCE!H16)/2) -> 0.13555458 | E18: - | G18: =BALANCE!B12/BALANCE!B28 -> 1.374688 | H18: =BALANCE!D12/BALANCE!D28 -> 1.4484074 | I18: =BALANCE!F12/BALANCE!F28 -> 1.9275247 | J18: =BALANCE!H12/BALANCE!H28 -> 1.9832721
B20: APALANCAMIENTO OPERATIVO | G20: APALANCAMIENTO TERCEROS
B21: 2024 | C21: 2023 | D21: 2022 | E21: 2021 | G21: 2024 | H21: 2023 | I21: 2022 | J21: 2021
B22: =('ESTADO DE RESULTADOS'!B6-COSTOS!E2-COSTOS!E3-COSTOS!E4-COSTOS!E12-COSTOS!E19)/('ESTADO DE RESULTADOS'!B8+'ESTADO DE RESULTADOS'!B9+'ESTADO DE RESULTADOS'!B10) -> 1.6398575 | C22: =('ESTADO DE RESULTADOS'!D6-COSTOS!D2-COSTOS!D3-COSTOS!D4-COSTOS!D12-COSTOS!D19)/('ESTADO DE RESULTADOS'!D8+'ESTADO DE RESULTADOS'!D9+'ESTADO DE RESULTADOS'!D10) -> 1.4108191 | D22: =('ESTADO DE RESULTADOS'!G6-COSTOS!C2-COSTOS!C3-COSTOS!C4-COSTOS!C12-COSTOS!C19)/('ESTADO DE RESULTADOS'!G8+'ESTADO DE RESULTADOS'!G9+'ESTADO DE RESULTADOS'!G10) -> 2.0030898 | E22: =('ESTADO DE RESULTADOS'!J6-COSTOS!B2-COSTOS!B3-COSTOS!B4-COSTOS!B12-COSTOS!B19)/('ESTADO DE RESULTADOS'!J8+'ESTADO DE RESULTADOS'!J9+'ESTADO DE RESULTADOS'!J10) -> -30.197454 | G22: =BALANCE!B25/BALANCE!B28 -> 0.37468796 | H22: =BALANCE!D25/BALANCE!D28 -> 0.44840743 | I22: =BALANCE!F25/BALANCE!F28 -> 0.92752469 | J22: =BALANCE!H25/BALANCE!H28 -> 0.98327214

Sheet GRAFICOS
